<?xml version="1.0" ?>
<!-- =================================================================================== -->
<!-- |    This document was autogenerated by xacro from robots/panda_arm_hand.urdf.xacro | -->
<!-- |    EDITING THIS FILE BY HAND IS NOT RECOMMENDED                                 | -->
<!-- =================================================================================== -->
<robot name="panda">
  <!-- If using a different frame with ${connected_to} param, make sure 'world' frame exists in the TF tree -->
  <joint name="panda_hand_joint" type="fixed">
    <parent link="panda_link8"/>
    <child link="panda_hand"/>
    <origin rpy="0 0 -0.7853981633974483" xyz="0 0 0"/>
  </joint>
  <link name="panda_hand">
    <visual>
      <geometry>
        <mesh filename="package://franka_panda_description/meshes/visual/hand.dae"/>
      </geometry>
    </visual>
    <collision>
      <geometry>
        <mesh filename="package://franka_panda_description/meshes/collision/hand.stl"/>
      </geometry>
    </collision>
    <inertial>
      <origin rpy="0 0 0" xyz="0 0.0015244 0.0275912"/>
      <mass value="0.73"/>
      <inertia ixx="0.00278560230025" ixy="0.0" ixz="0.0" iyy="0.000400033405336" iyz="0.0" izz="0.00256378041832"/>
    </inertial>
  </link>
  <link name="panda_leftfinger">
    <visual>
      <geometry>
        <mesh filename="package://franka_panda_description/meshes/visual/finger.dae"/>
      </geometry>
    </visual>
    <collision>
      <geometry>
        <mesh filename="package://franka_panda_description/meshes/collision/finger.stl"/>
      </geometry>
    </collision>
    <inertial>
      <origin rpy="0 0 0" xyz="0 0.0145644 0.0227941"/>
      <mass value="0.1"/>
      <inertia ixx="3.01220925051e-05" ixy="0.0" ixz="0.0" iyy="2.95873808038e-05" iyz="0.0" izz="6.95125211657e-06"/>
    </inertial>
  </link>
  <link name="panda_rightfinger">
    <visual>
      <origin rpy="0 0 3.141592653589793" xyz="0 0 0"/>
      <geometry>
        <mesh filename="package://franka_panda_description/meshes/visual/finger.dae"/>
      </geometry>
    </visual>
    <collision>
      <origin rpy="0 0 3.141592653589793" xyz="0 0 0"/>
      <geometry>
        <mesh filename="package://franka_panda_description/meshes/collision/finger.stl"/>
      </geometry>
    </collision>
    <inertial>
      <origin rpy="0 0 3.141592653589793" xyz="0 -0.0145644 0.0227941"/>
      <mass value="0.1"/>
      <inertia ixx="3.01220925051e-05" ixy="0.0" ixz="0.0" iyy="2.95873808038e-05" iyz="0.0" izz="6.95125211657e-06"/>
    </inertial>
  </link>
  <joint name="panda_finger_joint1" type="prismatic">
    <parent link="panda_hand"/>
    <child link="panda_leftfinger"/>
    <origin rpy="0 0 0" xyz="0 0 0.0584"/>
    <axis xyz="0 1 0"/>
    <limit effort="20" lower="0.0" upper="0.04" velocity="0.2"/>
    <dynamics damping="500.0" friction="0.0"/>
  </joint>
  <joint name="panda_finger_joint2" type="prismatic">
    <parent link="panda_hand"/>
    <child link="panda_rightfinger"/>
    <origin rpy="0 0 0" xyz="0 0 0.0584"/>
    <axis xyz="0 -1 0"/>
    <limit effort="20" lower="0.0" upper="0.04" velocity="0.2"/>
    <dynamics damping="500.0" friction="0.0"/>
    <mimic joint="panda_finger_joint1"/>
  </joint>
  <link name="world"/>
  <joint name="panda_to_world" type="fixed">
    <parent link="world"/>
    <child link="panda_link0"/>
    <origin rpy="0 0 0" xyz="0 0 0"/>
    <dynamics damping="1.0"/>
  </joint>
  <link name="panda_link0">
    <visual>
      <geometry>
        <mesh filename="package://franka_panda_description/meshes/visual/link0.dae"/>
      </geometry>
    </visual>
    <collision>
      <geometry>
        <mesh filename="package://franka_panda_description/meshes/collision/link0.stl"/>
      </geometry>
    </collision>
    <inertial>
      <origin rpy="0 0 0" xyz="0 0 0"/>
      <mass value="3.06"/>
      <inertia ixx="0.3" ixy="0.0" ixz="0.0" iyy="0.3" iyz="0.0" izz="0.3"/>
    </inertial>
  </link>
  <link name="panda_link1">
    <visual>
      <geometry>
        <mesh filename="package://franka_panda_description/meshes/visual/link1.dae"/>
      </geometry>
    </visual>
    <collision>
      <geometry>
        <mesh filename="package://franka_panda_description/meshes/collision/link1.stl"/>
      </geometry>
    </collision>
    <inertial>
      <origin rpy="0 0 0" xyz="3.875e-03 2.081e-03 -0.1750"/>
      <mass value="4.970684"/>
      <inertia ixx="7.0337e-01" ixy="-1.3900e-04" ixz="6.7720e-03" iyy="7.0661e-01" iyz="1.9169e-02" izz="9.1170e-03"/>
    </inertial>
  </link>
  <joint name="panda_joint1" type="revolute">
    <safety_controller k_position="100.0" k_velocity="40.0" soft_lower_limit="-2.8973" soft_upper_limit="2.8973"/>
    <origin rpy="0 0 0" xyz="0 0 0.333"/>
    <parent link="panda_link0"/>
    <child link="panda_link1"/>
    <axis xyz="0 0 1"/>
    <limit effort="87" lower="-2.8973" upper="2.8973" velocity="2.1750"/>
    <dynamics damping="10.0" friction="5.0"/>
  </joint>
  <link name="panda_link2">
    <visual>
      <geometry>
        <mesh filename="package://franka_panda_description/meshes/visual/link2.dae"/>
      </geometry>
    </visual>
    <collision>
      <geometry>
        <mesh filename="package://franka_panda_description/meshes/collision/link2.stl"/>
      </geometry>
    </collision>
    <inertial>
      <origin rpy="0 0 0" xyz="-3.141e-03 -2.872e-02 3.495e-03"/>
      <mass value="0.646926"/>
      <inertia ixx="7.9620e-03" ixy="-3.9250e-03" ixz="1.0254e-02" iyy="2.8110e-02" iyz="7.0400e-04" izz="2.5995e-02"/>
    </inertial>
  </link>
  <joint name="panda_joint2" type="revolute">
    <safety_controller k_position="100.0" k_velocity="40.0" soft_lower_limit="-1.7628" soft_upper_limit="1.7628"/>
    <origin rpy="-1.5707963267948966 0 0" xyz="0 0 0"/>
    <parent link="panda_link1"/>
    <child link="panda_link2"/>
    <axis xyz="0 0 1"/>
    <limit effort="87" lower="-1.7628" upper="1.7628" velocity="2.1750"/>
    <dynamics damping="5.0" friction="2.0"/>
  </joint>
  <link name="panda_link3">
    <visual>
      <geometry>
        <mesh filename="package://franka_panda_description/meshes/visual/link3.dae"/>
      </geometry>
    </visual>
    <collision>
      <geometry>
        <mesh filename="package://franka_panda_description/meshes/collision/link3.stl"/>
      </geometry>
    </collision>
    <inertial>
      <origin rpy="0 0 0" xyz="2.7518e-02 3.9252e-02 -6.6502e-02"/>
      <mass value="3.228604"/>
      <inertia ixx="3.7242e-02" ixy="-4.7610e-03" ixz="-1.1396e-02" iyy="3.6155e-02" iyz="-1.2805e-02" izz="1.0830e-02"/>
    </inertial>
  </link>
  <joint name="panda_joint3" type="revolute">
    <safety_controller k_position="100.0" k_velocity="40.0" soft_lower_limit="-2.8973" soft_upper_limit="2.8973"/>
    <origin rpy="1.5707963267948966 0 0" xyz="0 -0.316 0"/>
    <parent link="panda_link2"/>
    <child link="panda_link3"/>
    <axis xyz="0 0 1"/>
    <limit effort="87" lower="-2.8973" upper="2.8973" velocity="2.1750"/>
    <dynamics damping="5.0" friction="2.0"/>
  </joint>
  <link name="panda_link4">
    <visual>
      <geometry>
        <mesh filename="package://franka_panda_description/meshes/visual/link4.dae"/>
      </geometry>
    </visual>
    <collision>
      <geometry>
        <mesh filename="package://franka_panda_description/meshes/collision/link4.stl"/>
      </geometry>
    </collision>
    <inertial>
      <origin rpy="0 0 0" xyz="-5.317e-02 1.04419e-01 2.7454e-02"/>
      <mass value="3.587895"/>
      <inertia ixx="2.5853e-02" ixy="7.7960e-03" ixz="-1.3320e-03" iyy="1.9552e-02" iyz="8.6410e-03" izz="2.8323e-02"/>
    </inertial>
  </link>
  <joint name="panda_joint4" type="revolute">
    <safety_controller k_position="100.0" k_velocity="40.0" soft_lower_limit="-3.0718" soft_upper_limit="-0.0698"/>
    <origin rpy="1.5707963267948966 0 0" xyz="0.0825 0 0"/>
    <parent link="panda_link3"/>
    <child link="panda_link4"/>
    <axis xyz="0 0 1"/>
    <limit effort="87" lower="-3.0718" upper="-0.0698" velocity="2.1750"/>
    <dynamics damping="1.0" friction="0.5"/>
  </joint>
  <link name="panda_link5">
    <visual>
      <geometry>
        <mesh filename="package://franka_panda_description/meshes/visual/link5.dae"/>
      </geometry>
    </visual>
    <collision>
      <geometry>
        <mesh filename="package://franka_panda_description/meshes/collision/link5_1.stl"/>
      </geometry>
    </collision>
    <collision>
      <geometry>
        <mesh filename="package://franka_panda_description/meshes/collision/link5_2.stl"/>
      </geometry>
    </collision>
    <collision>
      <geometry>
        <mesh filename="package://franka_panda_description/meshes/collision/link5_3.stl"/>
      </geometry>
    </collision>
    <inertial>
      <origin rpy="0 0 0" xyz="-1.1953e-02 4.1065e-02 -3.8437e-02"/>
      <mass value="1.225946"/>
      <inertia ixx="3.5549e-02" ixy="-2.1170e-03" ixz="-4.0370e-03" iyy="2.9474e-02" iyz="2.2900e-04" izz="8.6270e-03"/>
    </inertial>
  </link>
  <joint name="panda_joint5" type="revolute">
    <safety_controller k_position="100.0" k_velocity="40.0" soft_lower_limit="-2.8973" soft_upper_limit="2.8973"/>
    <origin rpy="-1.5707963267948966 0 0" xyz="-0.0825 0.384 0"/>
    <parent link="panda_link4"/>
    <child link="panda_link5"/>
    <axis xyz="0 0 1"/>
    <limit effort="12" lower="-2.8973" upper="2.8973" velocity="2.6100"/>
    <dynamics damping="2.0" friction="1.0"/>
  </joint>
  <link name="panda_link6">
    <visual>
      <geometry>
        <mesh filename="package://franka_panda_description/meshes/visual/link6.dae"/>
      </geometry>
    </visual>
    <collision>
      <geometry>
        <mesh filename="package://franka_panda_description/meshes/collision/link6.stl"/>
      </geometry>
    </collision>
    <inertial>
      <origin rpy="0 0 0" xyz="6.0149e-02 -1.4117e-02 -1.0517e-02"/>
      <mass value="1.666555"/>
      <inertia ixx="1.9640e-03" ixy="1.0900e-04" ixz="-1.1580e-03" iyy="4.3540e-03" iyz="3.4100e-04" izz="5.4330e-03"/>
    </inertial>
  </link>
  <joint name="panda_joint6" type="revolute">
    <safety_controller k_position="100.0" k_velocity="40.0" soft_lower_limit="-0.0175" soft_upper_limit="3.7525"/>
    <origin rpy="1.5707963267948966 0 0" xyz="0 0 0"/>
    <parent link="panda_link5"/>
    <child link="panda_link6"/>
    <axis xyz="0 0 1"/>
    <limit effort="12" lower="-0.0175" upper="3.7525" velocity="2.6100"/>
    <dynamics damping="1.0" friction="0.5"/>
  </joint>
  <link name="panda_link7">
    <visual>
      <geometry>
        <mesh filename="package://franka_panda_description/meshes/visual/link7.dae"/>
      </geometry>
    </visual>
    <collision>
      <geometry>
        <mesh filename="package://franka_panda_description/meshes/collision/link7.stl"/>
      </geometry>
    </collision>
    <inertial>
      <origin rpy="0 0 0" xyz="1.0517e-02 -4.252e-03 6.1597e-02"/>
      <mass value="7.35522e-01"/>
      <inertia ixx="1.2516e-02" ixy="-4.2800e-04" ixz="-1.1960e-03" iyy="1.0027e-02" iyz="-7.4100e-04" izz="4.8150e-03"/>
    </inertial>
  </link>
  <joint name="panda_joint7" type="revolute">
    <safety_controller k_position="100.0" k_velocity="40.0" soft_lower_limit="-2.8973" soft_upper_limit="2.8973"/>
    <origin rpy="1.5707963267948966 0 0" xyz="0.088 0 0"/>
    <parent link="panda_link6"/>
    <child link="panda_link7"/>
    <axis xyz="0 0 1"/>
    <limit effort="12" lower="-2.8973" upper="2.8973" velocity="2.6100"/>
    <dynamics damping="1.0" friction="0.5"/>
  </joint>
  <link name="panda_link8">
    <inertial>
      <origin rpy="0 0 0" xyz="0 0 0"/>
      <mass value="0.0"/>
      <inertia ixx="0.001" ixy="0.0" ixz="0.0" iyy="0.001" iyz="0.0" izz="0.001"/>
    </inertial>
  </link>
  <joint name="panda_joint8" type="fixed">
    <origin rpy="0 0 0" xyz="0 0 0.107"/>
    <parent link="panda_link7"/>
    <child link="panda_link8"/>
    <axis xyz="0 0 0"/>
  </joint>
  <gazebo reference="panda_joint7">
    <implicitSpringDamper>1</implicitSpringDamper>
    <provideFeedback>true</provideFeedback>
  </gazebo>
  <gazebo reference="panda_joint1">
    <implicitSpringDamper>1</implicitSpringDamper>
    <provideFeedback>true</provideFeedback>
  </gazebo>
  <gazebo reference="panda_joint2">
    <implicitSpringDamper>1</implicitSpringDamper>
    <provideFeedback>true</provideFeedback>
  </gazebo>
  <gazebo reference="panda_joint3">
    <implicitSpringDamper>1</implicitSpringDamper>
    <provideFeedback>true</provideFeedback>
  </gazebo>
  <gazebo reference="panda_joint4">
    <implicitSpringDamper>1</implicitSpringDamper>
    <provideFeedback>true</provideFeedback>
  </gazebo>
  <gazebo reference="panda_joint5">
    <implicitSpringDamper>1</implicitSpringDamper>
    <provideFeedback>true</provideFeedback>
  </gazebo>
  <gazebo reference="panda_joint6">
    <implicitSpringDamper>1</implicitSpringDamper>
    <provideFeedback>true</provideFeedback>
  </gazebo>
  <gazebo reference="panda_finger_joint1">
    <implicitSpringDamper>1</implicitSpringDamper>
    <provideFeedback>true</provideFeedback>
  </gazebo>
  <gazebo reference="panda_finger_joint2">
    <implicitSpringDamper>1</implicitSpringDamper>
    <provideFeedback>true</provideFeedback>
  </gazebo>
  <!-- Adding FT sensor at wrist. This is not present in real robot and is used only for computing end-point effort directly, unlike in the real robot where it is estimated from the joint efforts. -->
  <gazebo reference="panda_joint7">
    <disableFixedJointLumping>true</disableFixedJointLumping>
    <sensor name="panda_joint7_force_torque" type="force_torque">
      <always_on>true</always_on>
      <visualize>false</visualize>
      <force_torque>
        <frame>sensor</frame>
        <measure_direction>child_to_parent</measure_direction>
      </force_torque>
    </sensor>
  </gazebo>
  <gazebo>
    <plugin filename="libgazebo_ros_ft_sensor.so" name="ft_sensor">
      <updateRate>30.0</updateRate>
      <topicName>/gazebo/robot/wrist/ft</topicName>
      <jointName>panda_joint7</jointName>
    </plugin>
  </gazebo>
  <!-- Configure self collision properties per link -->
  <!-- The gripper fingers do not have this flag otherwise the gripper would not be allowed to close correctly -->
  <gazebo reference="panda_link1">
    <selfCollide>true</selfCollide>
  </gazebo>
  <gazebo reference="panda_link2">
    <selfCollide>true</selfCollide>
  </gazebo>
  <gazebo reference="panda_link3">
    <selfCollide>true</selfCollide>
  </gazebo>
  <gazebo reference="panda_link4">
    <selfCollide>true</selfCollide>
  </gazebo>
  <gazebo reference="panda_link5">
    <selfCollide>true</selfCollide>
  </gazebo>
  <gazebo reference="panda_link6">
    <selfCollide>true</selfCollide>
  </gazebo>
  <gazebo reference="panda_link7">
    <selfCollide>true</selfCollide>
  </gazebo>
  <!-- Collision sensors on all links. This is not present on the real robot, it is used only in simulation to detect collisions. -->
  <!-- Link 0 is omitted because it is always in contact with the ground  -->
  <gazebo reference="panda_link1">
    <sensor name="panda_link1_contact" type="contact">
      <update_rate> 50 </update_rate>
      <always_on>true</always_on>
      <contact>
        <collision>panda_link1_collision</collision>
      </contact>
      <plugin filename="libgazebo_ros_bumper.so" name="link1_bumper">
        <bumperTopicName>panda_link1_collision</bumperTopicName>
        <frameName>panda_link1</frameName>
      </plugin>
    </sensor>
  </gazebo>
  <gazebo reference="panda_link2">
    <sensor name="panda_link2_contact" type="contact">
      <update_rate> 50 </update_rate>
      <always_on>true</always_on>
      <contact>
        <collision>panda_link2_collision</collision>
      </contact>
      <plugin filename="libgazebo_ros_bumper.so" name="link2_bumper">
        <bumperTopicName>panda_link2_collision</bumperTopicName>
        <frameName>panda_link2</frameName>
      </plugin>
    </sensor>
  </gazebo>
  <gazebo reference="panda_link3">
    <sensor name="panda_link3_contact" type="contact">
      <update_rate> 50 </update_rate>
      <always_on>true</always_on>
      <contact>
        <collision>panda_link3_collision</collision>
      </contact>
      <plugin filename="libgazebo_ros_bumper.so" name="link3_bumper">
        <bumperTopicName>panda_link3_collision</bumperTopicName>
        <frameName>panda_link3</frameName>
      </plugin>
    </sensor>
  </gazebo>
  <gazebo reference="panda_link4">
    <sensor name="panda_link4_contact" type="contact">
      <update_rate> 50 </update_rate>
      <always_on>true</always_on>
      <contact>
        <collision>panda_link4_collision</collision>
      </contact>
      <plugin filename="libgazebo_ros_bumper.so" name="link4_bumper">
        <bumperTopicName>panda_link4_collision</bumperTopicName>
        <frameName>panda_link4</frameName>
      </plugin>
    </sensor>
  </gazebo>
  <gazebo reference="panda_link5">
    <sensor name="panda_link5_contact" type="contact">
      <update_rate> 50 </update_rate>
      <always_on>true</always_on>
      <contact>
        <collision>panda_link5_collision</collision>
      </contact>
      <plugin filename="libgazebo_ros_bumper.so" name="link5_bumper">
        <bumperTopicName>panda_link5_collision</bumperTopicName>
        <frameName>panda_link5</frameName>
      </plugin>
    </sensor>
  </gazebo>
  <gazebo reference="panda_link6">
    <sensor name="panda_link6_contact" type="contact">
      <update_rate> 50 </update_rate>
      <always_on>true</always_on>
      <contact>
        <collision>panda_link6_collision</collision>
      </contact>
      <plugin filename="libgazebo_ros_bumper.so" name="link6_bumper">
        <bumperTopicName>panda_link6_collision</bumperTopicName>
        <frameName>panda_link6</frameName>
      </plugin>
    </sensor>
  </gazebo>
  <gazebo reference="panda_link7">
    <sensor name="panda_link7_contact" type="contact">
      <update_rate> 50 </update_rate>
      <always_on>true</always_on>
      <contact>
        <collision>panda_link7_collision</collision>
      </contact>
      <plugin filename="libgazebo_ros_bumper.so" name="link7_bumper">
        <bumperTopicName>panda_link7_collision</bumperTopicName>
        <frameName>panda_link7</frameName>
      </plugin>
    </sensor>
  </gazebo>
  <gazebo reference="panda_leftfinger">
    <sensor name="panda_leftfinger_contact" type="contact">
      <update_rate> 50 </update_rate>
      <always_on>true</always_on>
      <contact>
        <collision>panda_leftfinger_collision</collision>
      </contact>
      <plugin filename="libgazebo_ros_bumper.so" name="leftfinger_bumper">
        <bumperTopicName>panda_leftfinger_collision</bumperTopicName>
        <frameName>panda_leftfinger</frameName>
      </plugin>
    </sensor>
  </gazebo>
  <gazebo reference="panda_rightfinger">
    <sensor name="panda_rightfinger_contact" type="contact">
      <update_rate> 50 </update_rate>
      <always_on>true</always_on>
      <contact>
        <collision>panda_rightfinger_collision</collision>
      </contact>
      <plugin filename="libgazebo_ros_bumper.so" name="rightfinger_bumper">
        <bumperTopicName>panda_rightfinger_collision</bumperTopicName>
        <frameName>panda_rightfinger</frameName>
      </plugin>
    </sensor>
  </gazebo>
  <gazebo>
    <plugin filename="libpanda_gazebo_ros_control.so" name="panda_ros_control">
      <robotNamespace/>
      <robotSimType>panda_gazebo/PandaRobotHWSim</robotSimType>
      <controlPeriod>0.001</controlPeriod>
      <eStopTopic>sim_estop</eStopTopic>
    </plugin>
  </gazebo>
  <transmission name="panda_tran_1">
    <type>transmission_interface/SimpleTransmission</type>
    <joint name="panda_joint1">
      <hardwareInterface>hardware_interface/EffortJointInterface</hardwareInterface>
    </joint>
    <actuator name="panda_motor_1">
      <hardwareInterface>hardware_interface/EffortJointInterface</hardwareInterface>
      <mechanicalReduction>1</mechanicalReduction>
    </actuator>
  </transmission>
  <transmission name="panda_tran_2">
    <type>transmission_interface/SimpleTransmission</type>
    <joint name="panda_joint2">
      <hardwareInterface>hardware_interface/EffortJointInterface</hardwareInterface>
    </joint>
    <actuator name="panda_motor_2">
      <hardwareInterface>hardware_interface/EffortJointInterface</hardwareInterface>
      <mechanicalReduction>1</mechanicalReduction>
    </actuator>
  </transmission>
  <transmission name="panda_tran_3">
    <type>transmission_interface/SimpleTransmission</type>
    <joint name="panda_joint3">
      <hardwareInterface>hardware_interface/EffortJointInterface</hardwareInterface>
    </joint>
    <actuator name="panda_motor_3">
      <hardwareInterface>hardware_interface/EffortJointInterface</hardwareInterface>
      <mechanicalReduction>1</mechanicalReduction>
    </actuator>
  </transmission>
  <transmission name="panda_tran_4">
    <type>transmission_interface/SimpleTransmission</type>
    <joint name="panda_joint4">
      <hardwareInterface>hardware_interface/EffortJointInterface</hardwareInterface>
    </joint>
    <actuator name="panda_motor_4">
      <hardwareInterface>hardware_interface/EffortJointInterface</hardwareInterface>
      <mechanicalReduction>1</mechanicalReduction>
    </actuator>
  </transmission>
  <transmission name="panda_tran_5">
    <type>transmission_interface/SimpleTransmission</type>
    <joint name="panda_joint5">
      <hardwareInterface>hardware_interface/EffortJointInterface</hardwareInterface>
    </joint>
    <actuator name="panda_motor_5">
      <hardwareInterface>hardware_interface/EffortJointInterface</hardwareInterface>
      <mechanicalReduction>1</mechanicalReduction>
    </actuator>
  </transmission>
  <transmission name="panda_tran_6">
    <type>transmission_interface/SimpleTransmission</type>
    <joint name="panda_joint6">
      <hardwareInterface>hardware_interface/EffortJointInterface</hardwareInterface>
    </joint>
    <actuator name="panda_motor_6">
      <hardwareInterface>hardware_interface/EffortJointInterface</hardwareInterface>
      <mechanicalReduction>1</mechanicalReduction>
    </actuator>
  </transmission>
  <transmission name="panda_tran_7">
    <type>transmission_interface/SimpleTransmission</type>
    <joint name="panda_joint7">
      <hardwareInterface>hardware_interface/EffortJointInterface</hardwareInterface>
    </joint>
    <actuator name="panda_motor_7">
      <hardwareInterface>hardware_interface/EffortJointInterface</hardwareInterface>
      <mechanicalReduction>1</mechanicalReduction>
    </actuator>
  </transmission>
  <transmission name="panda_leftfinger">
    <type>transmission_interface/SimpleTransmission</type>
    <joint name="panda_finger_joint1">
      <hardwareInterface>hardware_interface/EffortJointInterface</hardwareInterface>
    </joint>
    <actuator name="panda_finger_joint1">
      <hardwareInterface>hardware_interface/EffortJointInterface</hardwareInterface>
      <mechanicalReduction>1</mechanicalReduction>
    </actuator>
  </transmission>
  <transmission name="panda_rightfinger">
    <type>transmission_interface/SimpleTransmission</type>
    <joint name="panda_finger_joint2">
      <hardwareInterface>hardware_interface/EffortJointInterface</hardwareInterface>
    </joint>
    <actuator name="panda_finger_joint2">
      <hardwareInterface>hardware_interface/EffortJointInterface</hardwareInterface>
      <mechanicalReduction>1</mechanicalReduction>
    </actuator>
  </transmission>

  <gazebo reference="panda_link0">
      <static>true</static>
      <turnGravityOff>true</turnGravityOff>
  </gazebo>
  <gazebo reference="panda_link1">
      <static>true</static>
      <turnGravityOff>true</turnGravityOff>
  </gazebo>
  <gazebo reference="panda_link2">
      <static>true</static>
      <turnGravityOff>true</turnGravityOff>
  </gazebo>
  <gazebo reference="panda_link3">
      <static>true</static>
      <turnGravityOff>true</turnGravityOff>
  </gazebo>
  <gazebo reference="panda_link4">
      <static>true</static>
      <turnGravityOff>true</turnGravityOff>
  </gazebo>
  <gazebo reference="panda_link5">
      <static>true</static>
      <turnGravityOff>true</turnGravityOff>
  </gazebo>
  <gazebo reference="panda_link6">
      <static>true</static>
      <turnGravityOff>true</turnGravityOff>
  </gazebo>
  <gazebo reference="panda_link7">
      <static>true</static>
      <turnGravityOff>true</turnGravityOff>
  </gazebo>
  <gazebo reference="panda_link8">
      <static>true</static>
      <turnGravityOff>true</turnGravityOff>
  </gazebo>
  <gazebo reference="panda_leftfinger">
      <static>true</static>
      <turnGravityOff>true</turnGravityOff>
  </gazebo>
  <gazebo reference="panda_rightfinger">
      <static>true</static>
      <turnGravityOff>true</turnGravityOff>
  </gazebo>



</robot>


<!-- <gazebo reference="base_link">
   <turnGravityOff>true</turnGravityOff>
</gazebo> -->
